Workbook

Sheet Start Here
B1: ChessLab: complete build and learning plan
B2: From your current static chess AI to a deployed full-stack AI learning app. Every step, every command, every file, and the lesson behind it.
B4: How to use this workbook
B5: 1. Dashboard | C5: Your progress by phase, updated automatically from the Tasks sheet. Set your weekly hours to see an estimated finish.
B6: 2. Tasks | C6: The plan: 178 small steps in 23 phases. Each row says what to do, the exact commands, which code file to use, which lesson explains it, and how you know it is done. Work top to bottom.
B7: 3. Lessons / Lesson Notes | C7: 58 lessons that teach the WHY and HOW behind each step, with self-check questions and free resources. Tasks link straight to the right lesson.
B8: 4. Code Index / Code | C8: Every source file, line by line, ready to copy into the path shown. Tasks link straight to the right file.
B9: 5. API Reference, Config & Env | C9: Every endpoint, environment variable and port in one place.
B10: 6. Checklists | C10: Security, privacy, deployment verification, engineering, AI evidence and portfolio checks for the release.
B11: 7. Troubleshooting | C11: Symptoms, causes and fixes for the problems you are most likely to hit (several were hit for real while preparing this plan).
B12: 8. Glossary, Resources, Interview Prep, Decisions | C12: Look up terms, find all links in one list, practise interview answers, and see how this plan differs from PROJECT_PLAN.md.
B14: What you edit (legend)
B15: Yellow cells | C15: The only cells you edit: Status (dropdown), Date done, My notes on Tasks and Lessons; hours per week on the Dashboard; Done/Practised columns on Checklists and Interview Prep. Blue text = your input.
B16: Status values | C16: Not started · In progress · Done · Skipped · Blocked. Rows colour themselves: green Done, amber In progress, red Blocked, grey Skipped.
B17: Example filled row | C17: Status: Done · Date done: 2026-10-24 · My notes: 'Pushed after a pull --rebase; Docker needed a restart after enabling WSL2.'
B18: Kinds of task | C18: Learn (study a lesson), Setup (install or configure), Build (write code), Test (prove it works), Deploy (put it live), Doc (write for readers).
B19: Core vs Stretch | C19: Core phases G0 and P0-P14 are the portfolio release (blue bands). Stretch phases S1-S7 are optional extras (green bands), fully specified for later.
B20: Owners | C20: Each step is owned by Srikanth (green) or Siva prasad (blue). Both (grey) means each of you does it on your own laptop. Hours are balanced inside every phase; see the team split on the Dashboard.
B21: Git | C21: One shared repository, everyone pushes to main. Before a step: git pull --rebase. After a step that changed files: git add -A, git commit -m "P3.05: ...", git push. Study and install steps have no Git commands.
B22: '→ Code: path' | C22: In the Commands column means: open that file on the Code sheet (the 'Code file' column links to it) and copy it to that path in your repository.
B23: Commands | C23: Written for Git Bash on Windows, on both laptops. Run them from the folder named in the task (usually the repo root, apps/web or services/backend). Docker commands with container paths start with MSYS_NO_PATHCONV=1 on purpose.
B25: What you will build
B26: The product | C26: ChessLab: play chess against an engine in the browser, import your Lichess games, see VERIFIED missed knight forks with the line and material they win, practise the same idea on new puzzles chosen for your level, and track honest progress.
B27: Architecture | C27: Browser (React + TypeScript; Stockfish WASM and your original engine in Web Workers) → FastAPI (validation, guest auth, ownership) → PostgreSQL (all data AND the job queue) ← Python worker (python-chess + native Stockfish: analysis and imports). Hosting: Vercel (frontend), Render (API, worker, Postgres).
B28: Where the AI is | C28: Search (Stockfish, integrated) · rules + verification (your fork detector) · a learner model (per-concept Elo driving adaptive practice) · rigorous evaluation (precision/recall with intervals, calibration) · optional LLM (Claude) that only rewords verified explanations. See lesson L37.
B29: Checkpoints | C29: A (end of P5): a stranger can play a full game on your public URL. B (end of P10): play/import → review → new exercise → graded attempt, live. Release 1.0 (end of P14): measured, documented, portfolio-ready.
B31: How this plan relates to PROJECT_PLAN.md
B32: Same destination, leaner path | C32: It follows the original blueprint but applies the review's recommendations: the game is played in the browser (server re-validates the PGN), and 'done' means the Core phases. Chess.com, hanging pieces, engine comparison, the pilot and ML extensions are fully planned as Stretch phases. Details: Decisions sheet.
B33: Local ports on THIS machine | C33: Other projects already use 5432 (Postgres), 8000 (API) and 5173 (Vite). ChessLab uses 5433 (Postgres), 8010 (API) and 5180 (web). See Config & Env.
B35: What was verified while building this plan
B36: ✓ 1 | C36: Repository (2026-10-22): this folder was initialised on main with a personal identity for this repository only (the global identity is the work account) and connected to github.com/msris93197-dev/ChessLab; access verified with git ls-remote. The first commit and push are step G0.03.
B37: ✓ 2 | C37: Backend: 43 automated tests pass on Python with real PostgreSQL 16: detector logic, grading, Elo, PGN parsing, LLM guards, hanging pieces, plus API integration tests for ownership, idempotency, FOR UPDATE SKIP LOCKED (4 threads × 30 jobs, no duplicates), stale-worker fencing, cancellation, practice flow, deletion and a concurrency regression.
B38: ✓ 3 | C38: Migrations: Alembic autogenerate created all tables from the models; 'alembic check' reported no drift.
B39: ✓ 4 | C39: Docker: the backend image builds and contains Stockfish 15.1; the full Compose stack (db → migrations → API → worker) started and served the app.
B40: ✓ 5 | C40: Real engine: the pipeline found a missed fork with Stockfish and produced a correct explanation; a sample game from low-strength engine self-play gave the public demo (18.Nf7 forking queen and rook).
B41: ✓ 6 | C41: Frontend: TypeScript compiles, Vitest passes, production build succeeds, lint is clean; Playwright in Chromium passed 3 frontend journeys and 2 full-stack journeys (play → resign → background analysis → review → practice → progress, and the public demo).
B42: ✓ 7 | C42: Live providers: the Lichess importer fetched and parsed real public games and handled 'user not found'; a 5-game import ran through the queue end to end; the Chess.com importer (stretch) fetched real games.
B43: ✓ 8 | C43: Bugs found and fixed during verification (now lessons): a get-or-create race exposed by React StrictMode (L30), the knight-vs-rook endgame that correctly produced no finding (L35), psycopg's -1 rowcount on bulk insert, port clashes with other local projects, Git Bash path rewriting.
B44: ✓ 9 | C44: Not verified here (needs your accounts): the actual Render and Vercel deployments, the Claude API call itself (guards are tested; the call needs your key), and the 300 MB puzzle download (the script was tested on a sample).
B45: ✓ 10 | C45: All 192 resource links were checked and resolve.
...

Sheet Dashboard
A1: ChessLab progress dashboard
A2: Everything below updates automatically from the Status column of the Tasks sheet. Edit only yellow cells (here: hours per week).
A4: Phase | B4: Name | C4: Type | D4: Checkpoint / goal | E4: Tasks | F4: Done | G4: % done | H4: Est. hrs | I4: Hrs done | J4: Hrs left
A5: G0 | B5: Repository and team setup | C5: Core | D5: Connect this folder to GitHub, make the first push, and get Siva prasad pushing to the same repository. | E5: =COUNTIF(Tasks!$B$2:$B$202,A5) | F5: =COUNTIFS(Tasks!$B$2:$B$202,A5,Tasks!$M$2:$M$202,"Done")+COUNTIFS(Tasks!$B$2:$B$202,A5,Tasks!$M$2:$M$202,"Skipped") | G5: =IF(E5=0,0,F5/E5) | H5: =SUMIF(Tasks!$B$2:$B$202,A5,Tasks!$L$2:$L$202) | I5: =SUMIFS(Tasks!$L$2:$L$202,Tasks!$B$2:$B$202,A5,Tasks!$M$2:$M$202,"Done") | J5: =H5-I5-SUMIFS(Tasks!$L$2:$L$202,Tasks!$B$2:$B$202,A5,Tasks!$M$2:$M$202,"Skipped")
A6: P0 | B6: Orientation and tool setup | C6: Core | D6: Install every tool, create accounts, understand the target architecture. | E6: =COUNTIF(Tasks!$B$2:$B$202,A6) | F6: =COUNTIFS(Tasks!$B$2:$B$202,A6,Tasks!$M$2:$M$202,"Done")+COUNTIFS(Tasks!$B$2:$B$202,A6,Tasks!$M$2:$M$202,"Skipped") | G6: =IF(E6=0,0,F6/E6) | H6: =SUMIF(Tasks!$B$2:$B$202,A6,Tasks!$L$2:$L$202) | I6: =SUMIFS(Tasks!$L$2:$L$202,Tasks!$B$2:$B$202,A6,Tasks!$M$2:$M$202,"Done") | J6: =H6-I6-SUMIFS(Tasks!$L$2:$L$202,Tasks!$B$2:$B$202,A6,Tasks!$M$2:$M$202,"Skipped")
A7: P1 | B7: Understand and preserve the original project | C7: Core | D7: Record what exists, protect it with Git, inventory licences. | E7: =COUNTIF(Tasks!$B$2:$B$202,A7) | F7: =COUNTIFS(Tasks!$B$2:$B$202,A7,Tasks!$M$2:$M$202,"Done")+COUNTIFS(Tasks!$B$2:$B$202,A7,Tasks!$M$2:$M$202,"Skipped") | G7: =IF(E7=0,0,F7/E7) | H7: =SUMIF(Tasks!$B$2:$B$202,A7,Tasks!$L$2:$L$202) | I7: =SUMIFS(Tasks!$L$2:$L$202,Tasks!$B$2:$B$202,A7,Tasks!$M$2:$M$202,"Done") | J7: =H7-I7-SUMIFS(Tasks!$L$2:$L$202,Tasks!$B$2:$B$202,A7,Tasks!$M$2:$M$202,"Skipped")
A8: P2 | B8: Repository scaffold and local database | C8: Core | D8: Monorepo folders, frontend and backend skeletons, Postgres in Docker. | E8: =COUNTIF(Tasks!$B$2:$B$202,A8) | F8: =COUNTIFS(Tasks!$B$2:$B$202,A8,Tasks!$M$2:$M$202,"Done")+COUNTIFS(Tasks!$B$2:$B$202,A8,Tasks!$M$2:$M$202,"Skipped") | G8: =IF(E8=0,0,F8/E8) | H8: =SUMIF(Tasks!$B$2:$B$202,A8,Tasks!$L$2:$L$202) | I8: =SUMIFS(Tasks!$L$2:$L$202,Tasks!$B$2:$B$202,A8,Tasks!$M$2:$M$202,"Done") | J8: =H8-I8-SUMIFS(Tasks!$L$2:$L$202,Tasks!$B$2:$B$202,A8,Tasks!$M$2:$M$202,"Skipped")
A9: P3 | B9: Backend foundations | C9: Core | D9: Settings, database models, migrations, guest sessions, errors, health checks, first tests. | E9: =COUNTIF(Tasks!$B$2:$B$202,A9) | F9: =COUNTIFS(Tasks!$B$2:$B$202,A9,Tasks!$M$2:$M$202,"Done")+COUNTIFS(Tasks!$B$2:$B$202,A9,Tasks!$M$2:$M$202,"Skipped") | G9: =IF(E9=0,0,F9/E9) | H9: =SUMIF(Tasks!$B$2:$B$202,A9,Tasks!$L$2:$L$202) | I9: =SUMIFS(Tasks!$L$2:$L$202,Tasks!$B$2:$B$202,A9,Tasks!$M$2:$M$202,"Done") | J9: =H9-I9-SUMIFS(Tasks!$L$2:$L$202,Tasks!$B$2:$B$202,A9,Tasks!$M$2:$M$202,"Skipped")
A10: P4 | B10: Playable game in the browser | C10: Core | D10: Board, rules, Stockfish WASM opponent, your original engine, promotion, PGN export. | E10: =COUNTIF(Tasks!$B$2:$B$202,A10) | F10: =COUNTIFS(Tasks!$B$2:$B$202,A10,Tasks!$M$2:$M$202,"Done")+COUNTIFS(Tasks!$B$2:$B$202,A10,Tasks!$M$2:$M$202,"Skipped") | G10: =IF(E10=0,0,F10/E10) | H10: =SUMIF(Tasks!$B$2:$B$202,A10,Tasks!$L$2:$L$202) | I10: =SUMIFS(Tasks!$L$2:$L$202,Tasks!$B$2:$B$202,A10,Tasks!$M$2:$M$202,"Done") | J10: =H10-I10-SUMIFS(Tasks!$L$2:$L$202,Tasks!$B$2:$B$202,A10,Tasks!$M$2:$M$202,"Skipped")
A11: P5 | B11: First public deployment (thin slice) | C11: Core | D11: Checkpoint A: a stranger can play a complete game on the public URL | E11: =COUNTIF(Tasks!$B$2:$B$202,A11) | F11: =COUNTIFS(Tasks!$B$2:$B$202,A11,Tasks!$M$2:$M$202,"Done")+COUNTIFS(Tasks!$B$2:$B$202,A11,Tasks!$M$2:$M$202,"Skipped") | G11: =IF(E11=0,0,F11/E11) | H11: =SUMIF(Tasks!$B$2:$B$202,A11,Tasks!$L$2:$L$202) | I11: =SUMIFS(Tasks!$L$2:$L$202,Tasks!$B$2:$B$202,A11,Tasks!$M$2:$M$202,"Done") | J11: =H11-I11-SUMIFS(Tasks!$L$2:$L$202,Tasks!$B$2:$B$202,A11,Tasks!$M$2:$M$202,"Skipped")
A12: P6 | B12: Saving games and the durable job queue | C12: Core | D12: Server re-validates games; Postgres queue with leases; the worker process with Stockfish. | E12: =COUNTIF(Tasks!$B$2:$B$202,A12) | F12: =COUNTIFS(Tasks!$B$2:$B$202,A12,Tasks!$M$2:$M$202,"Done")+COUNTIFS(Tasks!$B$2:$B$202,A12,Tasks!$M$2:$M$202,"Skipped") | G12: =IF(E12=0,0,F12/E12) | H12: =SUMIF(Tasks!$B$2:$B$202,A12,Tasks!$L$2:$L$202) | I12: =SUMIFS(Tasks!$L$2:$L$202,Tasks!$B$2:$B$202,A12,Tasks!$M$2:$M$202,"Done") | J12: =H12-I12-SUMIFS(Tasks!$L$2:$L$202,Tasks!$B$2:$B$202,A12,Tasks!$M$2:$M$202,"Skipped")
A13: P7 | B13: Importing history: Lichess and PGN upload | C13: Core | D13: Streaming provider import, dedupe, progress, cancellation, upload validation. | E13: =COUNTIF(Tasks!$B$2:$B$202,A13) | F13: =COUNTIFS(Tasks!$B$2:$B$202,A13,Tasks!$M$2:$M$202,"Done")+COUNTIFS(Tasks!$B$2:$B$202,A13,Tasks!$M$2:$M$202,"Skipped") | G13: =IF(E13=0,0,F13/E13) | H13: =SUMIF(Tasks!$B$2:$B$202,A13,Tasks!$L$2:$L$202) | I13: =SUMIFS(Tasks!$L$2:$L$202,Tasks!$B$2:$B$202,A13,Tasks!$M$2:$M$202,"Done") | J13: =H13-I13-SUMIFS(Tasks!$L$2:$L$202,Tasks!$B$2:$B$202,A13,Tasks!$M$2:$M$202,"Skipped")
A14: P8 | B14: Tactical analysis: verified missed knight forks | C14: Core | D14: Candidate generation, engine verification, evidence records, negative tests. | E14: =COUNTIF(Tasks!$B$2:$B$202,A14) | F14: =COUNTIFS(Tasks!$B$2:$B$202,A14,Tasks!$M$2:$M$202,"Done")+COUNTIFS(Tasks!$B$2:$B$202,A14,Tasks!$M$2:$M$202,"Skipped") | G14: =IF(E14=0,0,F14/E14) | H14: =SUMIF(Tasks!$B$2:$B$202,A14,Tasks!$L$2:$L$202) | I14: =SUMIFS(Tasks!$L$2:$L$202,Tasks!$B$2:$B$202,A14,Tasks!$M$2:$M$202,"Done") | J14: =H14-I14-SUMIFS(Tasks!$L$2:$L$202,Tasks!$B$2:$B$202,A14,Tasks!$M$2:$M$202,"Skipped")
A15: P9 | B15: Explanations, review screen and public demo | C15: Core | D15: Deterministic templates, replayable evidence, precomputed demo. | E15: =COUNTIF(Tasks!$B$2:$B$202,A15) | F15: =COUNTIFS(Tasks!$B$2:$B$202,A15,Tasks!$M$2:$M$202,"Done")+COUNTIFS(Tasks!$B$2:$B$202,A15,Tasks!$M$2:$M$202,"Skipped") | G15: =IF(E15=0,0,F15/E15) | H15: =SUMIF(Tasks!$B$2:$B$202,A15,Tasks!$L$2:$L$202) | I15: =SUMIFS(Tasks!$L$2:$L$202,Tasks!$B$2:$B$202,A15,Tasks!$M$2:$M$202,"Done") | J15: =H15-I15-SUMIFS(Tasks!$L$2:$L$202,Tasks!$B$2:$B$202,A15,Tasks!$M$2:$M$202,"Skipped")
A16: P10 | B16: Puzzle dataset and targeted practice | C16: Core | D16: Checkpoint B: play/import -> review -> new exercise -> graded attempt, live | E16: =COUNTIF(Tasks!$B$2:$B$202,A16) | F16: =COUNTIFS(Tasks!$B$2:$B$202,A16,Tasks!$M$2:$M$202,"Done")+COUNTIFS(Tasks!$B$2:$B$202,A16,Tasks!$M$2:$M$202,"Skipped") | G16: =IF(E16=0,0,F16/E16) | H16: =SUMIF(Tasks!$B$2:$B$202,A16,Tasks!$L$2:$L$202) | I16: =SUMIFS(Tasks!$L$2:$L$202,Tasks!$B$2:$B$202,A16,Tasks!$M$2:$M$202,"Done") | J16: =H16-I16-SUMIFS(Tasks!$L$2:$L$202,Tasks!$B$2:$B$202,A16,Tasks!$M$2:$M$202,"Skipped")
... A27: S7 | B27: Stretch: production extras | C27: Stretch | D27: Error tracking, separate workers, accounts that claim guest data. | E27: =COUNTIF(Tasks!$B$2:$B$202,A27) | F27: =COUNTIFS(Tasks!$B$2:$B$202,A27,Tasks!$M$2:$M$202,"Done")+COUNTIFS(Tasks!$B$2:$B$202,A27,Tasks!$M$2:$M$202,"Skipped") | G27: =IF(E27=0,0,F27/E27) | H27: =SUMIF(Tasks!$B$2:$B$202,A27,Tasks!$L$2:$L$202) | I27: =SUMIFS(Tasks!$L$2:$L$202,Tasks!$B$2:$B$202,A27,Tasks!$M$2:$M$202,"Done") | J27: =H27-I27-SUMIFS(Tasks!$L$2:$L$202,Tasks!$B$2:$B$202,A27,Tasks!$M$2:$M$202,"Skipped")
B29: Core (G0, P0-P14) | E29: =SUMIF(C5:C27,"Core",E5:E27) | F29: =SUMIF(C5:C27,"Core",F5:F27) | G29: =IF(E29=0,0,F29/E29) | H29: =SUMIF(C5:C27,"Core",H5:H27) | I29: =SUMIF(C5:C27,"Core",I5:I27) | J29: =H29-I29
B30: Stretch (S1-S7) | E30: =SUMIF(C5:C27,"Stretch",E5:E27) | F30: =SUMIF(C5:C27,"Stretch",F5:F27) | G30: =IF(E30=0,0,F30/E30) | H30: =SUMIF(C5:C27,"Stretch",H5:H27) | I30: =SUMIF(C5:C27,"Stretch",I5:I27) | J30: =H30-I30
B31: All phases | E31: =E29+E30 | F31: =F29+F30 | G31: =IF(E31=0,0,F31/E31) | H31: =H29+H30 | I31: =I29+I30 | J31: =J29+J30
B33: Your hours per week (edit) | E33: 12 | F33: ← assumption: change to your real weekly time
B34: Debugging / rework contingency (edit) | E34: 0.3 | F34: ← assumption: beginners usually need 25-50% extra for debugging and rework
B35: Weeks left for Core at that pace | E35: =IF(E33=0,0,J29*(1+E34)/E33)
B36: Weeks left for everything | E36: =IF(E33=0,0,J31*(1+E34)/E33)
B37: Lessons completed | E37: =COUNTIF(Lessons!F2:F60,"Done") | F37: =COUNTIF(Lessons!A2:A60,"*") | G37: =IF(F37=0,0,E37/F37)
B39: Team split (Both counts for each person) | E39: Steps | F39: Done | G39: % done | H39: Est. hrs | I39: Hrs done | J39: Hrs left
B40: Srikanth | E40: =COUNTIF(Tasks!$C$2:$C$202,"Srikanth")+COUNTIF(Tasks!$C$2:$C$202,"Both") | F40: =COUNTIFS(Tasks!$C$2:$C$202,"Srikanth",Tasks!$M$2:$M$202,"Done")+COUNTIFS(Tasks!$C$2:$C$202,"Both",Tasks!$M$2:$M$202,"Done") | G40: =IF(E40=0,0,F40/E40) | H40: =SUMIF(Tasks!$C$2:$C$202,"Srikanth",Tasks!$L$2:$L$202)+SUMIF(Tasks!$C$2:$C$202,"Both",Tasks!$L$2:$L$202) | I40: =SUMIFS(Tasks!$L$2:$L$202,Tasks!$C$2:$C$202,"Srikanth",Tasks!$M$2:$M$202,"Done")+SUMIFS(Tasks!$L$2:$L$202,Tasks!$C$2:$C$202,"Both",Tasks!$M$2:$M$202,"Done") | J40: =H40-I40
B41: Siva prasad | E41: =COUNTIF(Tasks!$C$2:$C$202,"Siva prasad")+COUNTIF(Tasks!$C$2:$C$202,"Both") | F41: =COUNTIFS(Tasks!$C$2:$C$202,"Siva prasad",Tasks!$M$2:$M$202,"Done")+COUNTIFS(Tasks!$C$2:$C$202,"Both",Tasks!$M$2:$M$202,"Done") | G41: =IF(E41=0,0,F41/E41) | H41: =SUMIF(Tasks!$C$2:$C$202,"Siva prasad",Tasks!$L$2:$L$202)+SUMIF(Tasks!$C$2:$C$202,"Both",Tasks!$L$2:$L$202) | I41: =SUMIFS(Tasks!$L$2:$L$202,Tasks!$C$2:$C$202,"Siva prasad",Tasks!$M$2:$M$202,"Done")+SUMIFS(Tasks!$L$2:$L$202,Tasks!$C$2:$C$202,"Both",Tasks!$M$2:$M$202,"Done") | J41: =H41-I41
B44: Notes
B45: Estimated hours are planning guesses for someone new to backend and AI work, including study time ('Learn' tasks contain the lesson reading). Re-estimate after Checkpoint A.
B46: 'Skipped' tasks count as finished for % done but not as hours done.
B47: Checkpoint A (end of P5): public playable game. Checkpoint B (end of P10): complete learning loop live. Release 1.0 (end of P14): portfolio-ready.

Sheet Tasks
A1: ID | B1: Phase | C1: Owner | D1: Kind | E1: Task | F1: How to do it (step by step) | G1: Commands / code to use (Git Bash) | H1: Git: before you start / save your work | I1: Code file | J1: Lessons | K1: Done when | L1: Est. hrs | M1: Status (edit) | N1: Date done (edit) | O1: My notes (edit)
E2: G0 Repository and team setup (Core) | F2: Connect this folder to GitHub, make the first push, and get Siva prasad pushing to the same repository.
A3: G0.01 | B3: G0 | C3: Srikanth | D3: Setup | E3: Check your GitHub login | F3: 1. Open Git Bash (or the VS Code terminal once it is set to Git Bash in P0.03). 2. Check that gh is logged in and that msris93197-dev is the ACTIVE account. This laptop is also logged in as srikanth-qaig (work), and pushes use whichever account is active. 3. Let git use gh for GitHub credentials (already set up on this laptop; running it again is harmless). | G3: gh auth status gh auth switch -u msris93197-dev # only if the work account is active gh auth setup-git | J3: L02 | K3: gh auth status shows msris93197-dev as the active account. | L3: 0.25 | M3: Not started
A4: G0.02 | B4: G0 | C4: Srikanth | D4: Setup | E4: Connect this folder to GitHub (done on 2026-10-22) | F4: Already done. For the record: 1. The folder was turned into a Git repository with main as the branch. 2. Your global Git identity is your work account, so this repository got its own identity (msris93197-dev with your private GitHub noreply email). It applies only inside this folder. 3. origin points to https://github.com/msris93197-dev/ChessLab.git. The commands below are the recipe if you ever need to redo it on another laptop. | G4: git init -b main git config user.name "msris93197-dev" git config user.email "280372735+msris93197-dev@users.noreply.github.com" git remote add origin https://github.com/msris93197-dev/ChessLab.git git remote -v | J4: L03 | K4: git remote -v shows the ChessLab URL. | L4: 0.25 | M4: Not started
A5: G0.03 | B5: G0 | C5: Srikanth | D5: Setup | E5: First commit and push (done on 2026-10-22) | F5: Already done: the .gitignore below, the original app and the plan files (in docs/) were committed, pushed to main and tagged original-app. | G5: → Code: .gitignore git add -A git commit -m "Import original chess AI and project plan" git push -u origin main git tag original-app && git push origin original-app | I5: C01 | J5: L03 | K5: GitHub shows the files and the tag original-app. | L5: 0.5 | M5: Not started
A6: G0.04 | B6: G0 | C6: Srikanth | D6: Setup | E6: Invite Siva prasad (done on 2026-10-22) | F6: Already done: satya-siva-prasad-yanamadala was invited with write access. He accepts it in G0.06. | G6: gh api -X PUT repos/msris93197-dev/ChessLab/collaborators/satya-siva-prasad-yanamadala -f permission=push gh api repos/msris93197-dev/ChessLab/invitations --jq '.[].invitee.login' | J6: L03 | K6: The invitation shows as pending (or accepted) for satya-siva-prasad-yanamadala. | L6: 0.25 | M6: Not started
A7: G0.05 | B7: G0 | C7: Srikanth | D7: Setup | E7: Switch to the simple workflow (undo the extra setup from the earlier plan) | F7: An earlier version of this plan added a journal file per step, a protected main branch and per-repo team settings. For two people that is overhead, so remove it: 1. Turn off branch protection, so both of you can push straight to main. 2. Delete the docs/journal folder. git log already records who did what and when. 3. Remove the two chesslab.* settings from this repository (nothing uses them any more). 4. Commit and push. | G7: gh api -X DELETE repos/msris93197-dev/ChessLab/branches/main/protection git pull --rebase git rm -r docs/journal git config --unset chesslab.me; git config --unset chesslab.partner git commit -m "G0.05: Remove journal folder, use a simple push-to-main workflow" git push | J7: L03 | K7: git push succeeds directly to main, and docs/journal is gone on GitHub. | L7: 0.25 | M7: Not started
A8: G0.06 | B8: G0 | C8: Siva prasad | D8: Setup | E8: Set up your laptop, accept the invitation and clone | F8: 1. Install Git for Windows (it includes Git Bash) and the GitHub CLI. Other tools come in chapter P0, where install steps are marked Both. 2. In Git Bash, log in with gh using your GitHub account (satya-siva-prasad-yanamadala) and let git use it. 3. Accept the invitation (or click the link in the invitation email). 4. Clone the repository. 5. Inside the clone, set your name and your GitHub noreply email (GitHub > Settings > Emails) so commits show up under your account. 6. Prove you can push: add yourself to the README and push. | G8: winget install --id Git.Git -e winget install --id GitHub.cli -e gh auth login # GitHub.com > HTTPS > log in with a web browser gh auth setup-git gh api user/repository_invitations --jq '.[] | "\(.id) \(.repository.full_name)"' gh api -X PATCH user/repository_invitations/INVITATION_ID mkdir -p ~/projects && cd ~/projects gh repo clone msris93197-dev/ChessLab && cd ChessLab git config user.name "Siva prasad" git config user.email "YOUR_ID+satya-siva-prasad-yanamadala@users.noreply.github.com" printf '\nBuilt by Srikanth and Siva prasad.\n' >> README.md git add README.md && git commit -m "G0.06: Add team to README" && git push | J8: L02, L03, L59 | K8: Your README commit is visible on GitHub under your name. | L8: 1 | M8: Not started
E9: P0 Orientation and tool setup (Core) | F9: Install every tool, create accounts, understand the target architecture.
A10: P0.01 | B10: P0 | C10: Srikanth | D10: Learn | E10: Read the Start Here sheet and the architecture summary | F10: 1. Read the Start Here sheet fully (10 min). 2. Read lesson L37 (what 'AI' means here) so you can describe the project honestly from day one. 3. Skim the Phase list on the Dashboard: Core phases P0-P14 are the portfolio release; S1-S7 are optional. 4. In a notebook, write the one-sentence pitch in your own words. | J10: L37 | K10: You can explain the 4 runtime parts (browser app, API, worker, Postgres) and what each does. | L10: 0.5 | M10: Not started
A11: P0.02 | B11: P0 | C11: Srikanth | D11: Learn | E11: Learn the web basics | F11: Study lesson L01. Open any website, press F12 > Network, reload, click a request and identify method, URL, status, request headers and response body. | J11: L01 | K11: You can name the parts of an HTTP request/response from a real example. | L11: 1.5 | M11: Not started
A12: P0.03 | B12: P0 | C12: Both | D12: Setup | E12: Install Git for Windows and make Git Bash your terminal | F12: 1. Git is already installed on Srikanth's laptop (git version 2.50). Siva prasad installed it in G0.06. 2. Make Git Bash the default terminal in VS Code: Ctrl+Shift+P > 'Terminal: Select Default Profile' > Git Bash. Every command in this manual is written for Git Bash. 3. Do not set a global name or email for ChessLab: each of you set it inside the repository (G0.02, G0.06). Srikanth's global identity stays the work account for work projects. | G12: git --version git config --local --get-regexp 'user\.' # run inside the ChessLab folder | J12: L03 | K12: VS Code opens Git Bash by default and git config --local shows your personal identity. | L12: 0.25 | M12: Not started
A13: P0.04 | B13: P0 | C13: Siva prasad | D13: Learn | E13: Learn the terminal: Git Bash on Windows | F13: Study lesson L02. In Git Bash practise: cd /d/my_learning/Chess-AI (Srikanth) or cd ~/projects/ChessLab (Siva prasad), pwd, ls -la, export TEST=hi, echo $TEST, cat README.md, history. | J13: L02 | K13: You can move between folders and set an environment variable for one session in Git Bash. | L13: 1 | M13: Not started
A14: P0.05 | B14: P0 | C14: Both | D14: Setup | E14: Install VS Code extensions | F14: Install in VS Code: Python (Microsoft), Pylance, Ruff, ESLint (optional), Prettier (optional), Docker, Playwright Test for VSCode, GitLens (optional), Even Better TOML, Rainbow CSV (helps labelling in P12). | G14: code --install-extension ms-python.python code --install-extension charliermarsh.ruff code --install-extension ms-azuretools.vscode-docker code --install-extension ms-playwright.playwright code --install-extension tamasfe.even-better-toml code --install-extension mechatroniks.rainbow-csv | K14: Extensions visible in the Extensions panel. | L14: 0.25 | M14: Not started
A15: P0.06 | B15: P0 | C15: Both | D15: Setup | E15: Install Node.js LTS | F15: Node 22 is already installed here (node v22). Check with node --version and npm --version. If you ever need another version, use nvm-windows. Node runs Vite, Vitest and Playwright. | G15: node --version npm --version | J15: L04 | K15: node --version prints v22 or newer. | L15: 0.25 | M15: Not started
A16: P0.07 | B16: P0 | C16: Both | D16: Setup | E16: Install uv and a project Python (3.12) | F16: 1. uv is already installed on Srikanth's laptop (~/.local/bin/uv). Each of you checks with uv --version. 2. If it is missing, install it with the official installer (the first command runs Windows' installer from Git Bash), or with winget. 3. Close and reopen Git Bash so the new PATH is picked up. 4. Install Python 3.12 managed by uv (3.14 is very new; 3.12 has the widest library support). | G16: uv --version || powershell.exe -ExecutionPolicy ByPass -c "irm https://astral.sh/uv/install.ps1 | iex" # alternative: winget install --id astral-sh.uv -e uv python install 3.12 uv python list | J16: L04, L11 | K16: uv --version works and 'uv python list' shows a 3.12 interpreter. | L16: 0.5 | M16: Not started
A17: P0.08 | B17: P0 | C17: Both | D17: Setup | E17: Install Docker Desktop with WSL2 | F17: 1. Docker 29 is already installed here. Open Docker Desktop and make sure it says 'Engine running'. 2. Settings > General: 'Use the WSL 2 based engine' is on. Settings > Resources: at least 4 GB memory. 3. Test with hello-world. 4. IMPORTANT for this machine: other projects already use ports 5432, 5434, 8000, 8080 and 5173. ChessLab therefore uses 5433 (Postgres), 8010 (API) and 5180 (web). | G17: docker --version docker run --rm hello-world docker ps --format "{{.Names}} {{.Ports}}" | J17: L15 | K17: hello-world prints its welcome message; you know which ports are already taken. | L17: 0.5 | M17: Not started
A18: P0.09 | B18: P0 | C18: Both | D18: Setup | E18: Create the accounts you will need | F18: Create (free) accounts: GitHub (you have one: srikanth-qaig), Vercel (sign in with GitHub), Render (sign in with GitHub), Lichess (to test imports with your own games). Optional later: Anthropic Console (stretch S3 only). Do NOT create paid resources yet. | J18: L48 | K18: You can log in to GitHub, Vercel and Render with your GitHub identity. | L18: 0.5 | M18: Not started
A19: P0.10 | B19: P0 | C19: Srikanth | D19: Learn | E19: Decide your hosting budget | F19: Open render.com/pricing and vercel.com/pricing. Note the current price of: Render web service (always-on, smallest), background worker, Postgres (smallest paid). Vercel Hobby is free for personal projects. Write a monthly ceiling (for example US$20-25) in your notebook. You can develop for weeks locally before paying anything; you only need paid Render plans from Phase 5 onwards (free plans sleep and free databases expire). | J19: L48 | K19: A written monthly budget and the plan names you will use. | L19: 0.5 | M19: Not started
A20: P0.11 | B20: P0 | C20: Siva prasad | D20: Learn | E20: Learn Git fundamentals | F20: Study lesson L03. Do the first 4 levels of learngitbranching.js.org. | J20: L03 | K20: You can create a branch, commit, and merge it locally. | L20: 1.5 | M20: Not started
E21: P1 Understand and preserve the original project (Core) | F21: Record what exists, protect it with Git, inventory licences.
A22: P1.01 | B22: P1 | C22: Siva prasad | D22: Learn | E22: Run the original app and record its behaviour | F22: 1. Open D:\my_learning\Chess-AI\index.html in a browser (double-click, or VS Code 'Live Server'). 2. Try every control: start, undo, redo, depth selectors, opening buttons (Ruy Lopez, Italian, Sicilian), computer vs computer, hint. 3. Note what works and any bugs (for example: promotion always becomes a queen; long thinking freezes the page at depth 4+). 4. Save notes in docs/baseline-notes.md (create the docs folder). | J22: L10 | K22: docs/baseline-notes.md lists working features, known defects and 3 sample positions (FENs) you tested. | L22: 1 | M22: Not started
A23: P1.02 | B23: P1 | C23: Srikanth | D23: Learn | E23: Understand your original engine | F23: Read js/main.js lines 35-309 with lesson L10 open: weights, pst_w/pst_b (piece-square tables), evaluateBoard (incremental evaluation), minimax with alpha-beta. Write 5 bullet points in baseline-notes.md: how evaluation works, why moves are shuffled, what alpha/beta do, why there is no quiescence search, why promotions are forced to queen. | J23: L10 | K23: You can explain your engine's search and evaluation in 2 minutes. | L23: 2 | M23: Not started
A24: P1.03 | B24: P1 | C24: Srikanth | D24: Setup | E24: Confirm the safety tag on GitHub | F24: The original app was tagged original-app in G0.03. Confirm the tag is on GitHub and that you can look at the old app, then come back to main. | G24: git fetch --tags git ls-remote --tags origin git switch --detach original-app && ls && git switch - | H24: BEFORE YOU START git pull --rebase SAVE YOUR WORK git add -A git status # nothing listed? then there is nothing to commit for this step git commit -m "P1.03: Confirm the safety tag on GitHub" git push # rejected? git pull --rebase, then git push again | J24: L03 | K24: git ls-remote --tags origin lists refs/tags/original-app. | L24: 0.5 | M24: Not started
A25: P1.04 | B25: P1 | C25: Siva prasad | D25: Doc | E25: Create a licence inventory | F25: 1. List third-party parts of the original app: js/chess.js (BSD-2, from chess.js 0.x), chessboard.js 1.0 (MIT, from unpkg), jQuery, Bootstrap 4, Font Awesome kit, piece images in img/chesspieces/wikipedia (Wikimedia origin), piece-square tables adapted from Sunfish (GPLv3, see the comment in main.js). 2. Start docs/THIRD_PARTY_NOTICES.md from the template (Code sheet). 3. Decide your repository licence. Recommended: GPLv3 (compatible with Stockfish, python-chess and Sunfish). Add a LICENSE file (GitHub > Add file > Create new file > name LICENSE > 'Choose a license template'). | G25: → Code: docs/THIRD_PARTY_NOTICES_TEMPLATE.md | H25: BEFORE YOU START git pull --rebase SAVE YOUR WORK git add -A git status # nothing listed? then there is nothing to commit for this step git commit -m "P1.04: Create a licence inventory" git push # rejected? git pull --rebase, then git push again | I25: C83 | J25: L55 | K25: LICENSE and docs/THIRD_PARTY_NOTICES.md exist in the repo. | L25: 1 | M25: Not started
A26: P1.05 | B26: P1 | C26: Siva prasad | D26: Doc | E26: Write acceptance stories | F26: Turn the visitor journey into testable sentences in docs/acceptance.md. Examples: - A guest choosing Black sees a legal engine opening move and can reply without refreshing. - After resigning, 'Review game' opens a review that shows analysis coverage. - A missed fork shows the alternative move, the line, the material gain and a 'Practice this idea' button. - Practising gives a different position; the solution is never sent to the browser. - A second guest cannot read the first guest's games or jobs. - 'Delete my data' makes the old token stop working. Write 15-25 such stories; each later task's 'Done when' should map to one. | H26: BEFORE YOU START git pull --rebase SAVE YOUR WORK git add -A git status # nothing listed? then there is nothing to commit for this step git commit -m "P1.05: Write acceptance stories" git push # rejected? git pull --rebase, then git push again | J26: L23 | K26: docs/acceptance.md with at least 15 stories. | L26: 1 | M26: Not started
A27: P1.06 | B27: P1 | C27: Srikanth | D27: Setup | E27: Agree who does what for the next chapters | F27: 1. Look at the owner labels for P2-P4 and swap any step one of you would rather do, keeping hours roughly even. 2. Agree the habit for every step: git pull --rebase before you start, commit and push when it works. Push small and often so you rarely clash. | G27: git log --oneline -5 | H27: BEFORE YOU START git pull --rebase SAVE YOUR WORK git add -A git status # nothing listed? then there is nothing to commit for this step git commit -m "P1.06: Agree who does what for the next chapters" git push # rejected? git pull --rebase, then git push again | J27: L03 | K27: You both know which P2-P4 steps are yours. | L27: 0.1 | M27: Not started
E28: P2 Repository scaffold and local database (Core) | F28: Monorepo folders, frontend and backend skeletons, Postgres in Docker.
A29: P2.01 | B29: P2 | C29: Srikanth | D29: Setup | E29: Create the folder structure | F29: Create the monorepo layout. Keep the original files in the root for now (they are your baseline; you remove them only after Phase 4 has parity). | G29: mkdir -p apps services data/manifests evaluation/labels evaluation/reports docs/decisions ops .github/workflows ls | H29: BEFORE YOU START git pull --rebase SAVE YOUR WORK git add -A git status # nothing listed? then there is nothing to commit for this step git commit -m "P2.01: Create the folder structure" git push # rejected? git pull --rebase, then git push again | J29: L11 | K29: The folders exist next to index.html, js/, css/. | L29: 0.25 | M29: Not started
A30: P2.02 | B30: P2 | C30: Srikanth | D30: Build | E30: Add the root .gitignore | F30: Create .gitignore in the repo root with the content from the Code sheet. It keeps node_modules, .venv, caches, .env files and big data dumps out of Git. | G30: → Code: .gitignore | H30: BEFORE YOU START git pull --rebase SAVE YOUR WORK git add -A git status # nothing listed? then there is nothing to commit for this step git commit -m "P2.02: Add the root .gitignore" git push # rejected? git pull --rebase, then git push again | I30: C01 | J30: L03, L18 | K30: git status does not show node_modules or .venv after later installs. | L30: 0.1 | M30: Not started
A31: P2.03 | B31: P2 | C31: Srikanth | D31: Build | E31: Scaffold the React + TypeScript app with Vite | F31: 1. From the repo root create apps/web with the official template. 2. Install and run it once. 3. Replace vite.config.ts with the Code sheet version (fixes port 5180). 4. Open http://localhost:5180: you should see the Vite + React page. | G31: → Code: apps/web/vite.config.ts cd apps npm create vite@latest web -- --template react-ts cd web npm install # replace vite.config.ts (Code sheet), then: npm run dev | H31: BEFORE YOU START git pull --rebase SAVE YOUR WORK git add -A git status # nothing listed? then there is nothing to commit for this step git commit -m "P2.03: Scaffold the React + TypeScript app with Vite" git push # rejected? git pull --rebase, then git push again | I31: C16 | J31: L07, L06 | K31: The Vite starter page loads on http://localhost:5180. | L31: 0.5 | M31: Not started
A32: P2.04 | B32: P2 | C32: Srikanth | D32: Setup | E32: Install the frontend libraries (pinned majors) | F32: Install chess rules, the board, routing and the Stockfish WASM build. Pin the major versions this plan was verified with: chess.js 1.x, react-chessboard 4.x (v5 has a different API), react-router-dom 6.x. Then add test tools. | G32: cd apps/web npm install chess.js@1 react-chessboard@4 react-router-dom@6 stockfish npm install -D vitest @playwright/test npx playwright install chromium | H32: BEFORE YOU START git pull --rebase SAVE YOUR WORK git add -A git status # nothing listed? then there is nothing to commit for this step git commit -m "P2.04: Install the frontend libraries" git push # rejected? git pull --rebase, then git push again | J32: L04 | K32: package.json lists chess.js ^1, react-chessboard ^4, react-router-dom ^6, stockfish; package-lock.json exists. | L32: 0.5 | M32: Not started
A33: P2.05 | B33: P2 | C33: Srikanth | D33: Setup | E33: Create the Python backend project with uv | F33: 1. Create services/backend as a uv project on Python 3.12. 2. Add runtime and dev dependencies (uv writes pyproject.toml and uv.lock). 3. Create the package folders with empty __init__.py files? Not required (namespace packages work) but recommended for tooling: app/, app/api, app/analysis, app/domain, app/explain, app/importers, app/jobs, app/learning, app/practice, tests/. 4. Add the [tool.pytest.ini_options] and [tool.ruff] sections from the Code sheet's pyproject.toml. 5. Delete the sample main.py (or hello.py) that uv init created: the real entry point is app/main.py. | G33: → Code: services/backend/pyproject.toml cd services uv init backend --python 3.12 --no-workspace cd backend uv add fastapi "uvicorn[standard]" sqlalchemy "psycopg[binary]" alembic pydantic-settings chess httpx python-multipart uv add --dev pytest ruff zstandard mkdir -p app/{api,analysis,domain,explain,importers,jobs,learning,practice} tests touch app/__init__.py app/{api,analysis,domain,explain,importers,jobs,learning,practice}/__init__.py rm -f main.py hello.py | H33: BEFORE YOU START git pull --rebase SAVE YOUR WORK git add -A git status # nothing listed? then there is nothing to commit for this step git commit -m "P2.05: Create the Python backend project with uv" git push # rejected? git pull --rebase, then git push again | I33: C03 | J33: L11, L04 | K33: uv run python -c "import fastapi, chess, sqlalchemy; print('ok')" prints ok. | L33: 0.75 | M33: Not started
A34: P2.06 | B34: P2 | C34: Srikanth | D34: Setup | E34: Start Postgres with Docker Compose | F34: 1. Put compose.yaml (Code sheet) in the repo root. For now you only start the db service. 2. Start it and check it is healthy. 3. Connect with psql inside the container and run SELECT version(); | G34: → Code: compose.yaml docker compose up -d db docker compose ps docker compose exec db psql -U chesslab -d chesslab -c "SELECT version();" | H34: BEFORE YOU START git pull --rebase SAVE YOUR WORK git add -A git status # nothing listed? then there is nothing to commit for this step git commit -m "P2.06: Start Postgres with Docker Compose" git push # rejected? git pull --rebase, then git push again | I34: C02 | J34: L15, L26 | K34: docker compose ps shows db as healthy on port 5433. | L34: 0.5 | M34: Not started
A35: P2.07 | B35: P2 | C35: Siva prasad | D35: Learn | E35: Learn SQL basics on the real database | F35: Study lesson L14. In psql, create a scratch table, insert, select, update, delete, then drop it. Try a UNIQUE constraint violation on purpose and read the error. | G35: docker compose exec -T db psql -U chesslab -d chesslab <<'SQL' CREATE TABLE scratch (id int PRIMARY KEY, name text UNIQUE); INSERT INTO scratch VALUES (1, 'a'); INSERT INTO scratch VALUES (2, 'a'); -- fails: unique violation (on purpose) INSERT INTO scratch VALUES (2, 'a') ON CONFLICT DO NOTHING; -- no error, nothing inserted SELECT * FROM scratch; DROP TABLE scratch; SQL # to explore by hand instead: winpty docker compose exec db psql -U chesslab -d chesslab | J35: L14 | K35: You have seen a unique violation and ON CONFLICT DO NOTHING behave differently. | L35: 3 | M35: Not started
A36: P2.08 | B36: P2 | C36: Srikanth | D36: Setup | E36: Commit the scaffold | F36: Before this commit, make sure no node_modules, .venv or .env files would be committed. | G36: git status --short | grep -E 'node_modules|\.venv|\.env$' && echo 'STOP: remove these before committing' || echo 'clean' | H36: BEFORE YOU START git pull --rebase SAVE YOUR WORK git add -A git status # nothing listed? then there is nothing to commit for this step git commit -m "P2.08: Commit the scaffold" git push # rejected? git pull --rebase, then git push again | J36: L03 | K36: A clean commit with apps/web, services/backend, compose.yaml. | L36: 0.1 | M36: Not started
E37: P3 Backend foundations (Core) | F37: Settings, database models, migrations, guest sessions, errors, health checks, first tests.
A38: P3.01 | B38: P3 | C38: Siva prasad | D38: Learn | E38: Learn FastAPI basics | F38: Study lesson L13 and do the first 6 pages of the official FastAPI tutorial in a scratch file (not in the project). | J38: L12, L13 | K38: You wrote and called a scratch endpoint with a Pydantic body. | L38: 5 | M38: Not started
A39: P3.02 | B39: P3 | C39: Srikanth | D39: Build | E39: Add typed settings (app/config.py) | F39: Create app/config.py from the Code sheet. Read every field and its comment. Note the validator that converts postgres:// and postgresql:// to postgresql+psycopg:// (Render gives the former). Copy services/backend/.env.example to .env (never commit .env). | G39: → Code: services/backend/app/config.py → Code: services/backend/.env.example cp .env.example .env | H39: BEFORE YOU START git pull --rebase SAVE YOUR WORK git add -A git status # nothing listed? then there is nothing to commit for this step git commit -m "P3.02: Add typed settings" git push # rejected? git pull --rebase, then git push again | I39: C05, C04 | J39: L18 | K39: uv run python -c "from app.config import get_settings; print(get_settings().database_url)" prints the 5433 URL. | L39: 0.5 | M39: Not started
A40: P3.03 | B40: P3 | C40: Siva prasad | D40: Build | E40: Add the database engine and session (app/db.py) | F40: Create app/db.py. Understand: Base (all models inherit), engine (connection pool, pool_pre_ping), SessionLocal, and get_db (one session per request, always closed). | G40: → Code: services/backend/app/db.py | H40: BEFORE YOU START git pull --rebase SAVE YOUR WORK git add -A git status # nothing listed? then there is nothing to commit for this step git commit -m "P3.03: Add the database engine and session" git push # rejected? git pull --rebase, then git push again | I40: C06 | J40: L16 | K40: File created; you can explain flush vs commit. | L40: 0.5 | M40: Not started
...

Sheet Lessons
A1: ID | B1: Lesson | C1: Level | D1: Minutes | E1: Used in phases | F1: Status (edit) | G1: Open | H1: My notes (edit)
A2: L01 | B2: How the web works: browsers, servers, HTTP and JSON | C2: Beginner | D2: 60 | E2: P0, P3, P4 | F2: Not started | G2: Open →
A3: L02 | B3: The terminal on Windows: Git Bash, paths and environment variables | C3: Beginner | D3: 45 | E3: P0 and every phase | F3: Not started | G3: Open →
A4: L03 | B4: Git and GitHub: commits, branches, pull requests | C4: Beginner | D4: 75 | E4: P0, P1 and every phase | F4: Not started | G4: Open →
A5: L04 | B5: Package managers and lockfiles (npm for JavaScript, uv for Python) | C5: Beginner | D5: 40 | E5: P2, P3, P4 | F5: Not started | G5: Open →
A6: L05 | B6: TypeScript essentials for this project | C6: Beginner | D6: 90 | E6: P4, P9, P10 | F6: Not started | G6: Open →
A7: L06 | B7: React fundamentals: components, props, state, effects and refs | C7: Beginner | D7: 150 | E7: P4, P9, P10, P11 | F7: Not started | G7: Open →
A8: L07 | B8: Vite, dev servers and production builds | C8: Beginner | D8: 30 | E8: P2, P4, P5 | F8: Not started | G8: Open →
A9: L08 | B9: Web Workers: keeping the page responsive while an engine thinks | C9: Intermediate | D9: 40 | E9: P4 | F9: Not started | G9: Open →
A10: L09 | B10: Chess notation for programmers: FEN, PGN, SAN and UCI | C10: Beginner | D10: 45 | E10: P4, P6, P8, P10 | F10: Not started | G10: Open →
A11: L10 | B11: How chess engines work: minimax, alpha-beta, evaluation, and Stockfish over UCI | C11: Intermediate | D11: 90 | E11: P1, P4, P8, S4 | F11: Not started | G11: Open →
A12: L11 | B12: Python projects: virtual environments, packages, modules and imports (with uv) | C12: Beginner | D12: 60 | E12: P2, P3 | F12: Not started | G12: Open →
A13: L12 | B13: Designing a REST API and choosing status codes | C13: Beginner | D13: 45 | E13: P3, P6, P7, P10 | F13: Not started | G13: Open →
... A60: L59 | B60: Sharing one repository as two people: pull, commit, push and fixing conflicts | C60: Beginner | D60: 30 | E60: G0 and every chapter | F60: Not started | G60: Open →
B62: Total study time (hours) | D62: =SUM(D2:D60)/60
B63: Lessons marked Done | D63: =COUNTIF(F2:F60,"Done")

Sheet Lesson Notes
A1: Lesson notes. Each lesson: why it matters, the core concepts, how it is used in ChessLab, common mistakes, self-check questions and resources (click to open).
A3: L01 | B3: How the web works: browsers, servers, HTTP and JSON · Beginner · about 60 min · used in P0, P3, P4
B4: ↑ back to Lessons index
A5: Why it matters | B5: Everything in ChessLab is a conversation between a browser (the React app) and a server (the FastAPI app). If you understand what a request and a response are, every later lesson becomes 'just details'.
A6: Concept 1 | B6: Client and server: the browser is a client. It downloads HTML, CSS and JavaScript from a static host (Vercel), then runs that JavaScript. The JavaScript then talks to a different program, the API server (Render), which owns the database.
A7: Concept 2 | B7: An HTTP request has: a METHOD (GET = read, POST = create/act, DELETE = remove, PUT/PATCH = update), a URL path (/v1/games/123), HEADERS (metadata such as Authorization: Bearer <token>, Content-Type: application/json) and an optional BODY (usually JSON).
A8: Concept 3 | B8: An HTTP response has: a STATUS CODE (200 OK, 201 Created, 204 No Content, 400/422 bad input, 401 not logged in, 404 not found, 409 conflict, 429 too many requests, 500 server bug), headers and a body.
A9: Concept 4 | B9: JSON is plain text that looks like JavaScript objects: {"game_id": "abc", "moves": ["e2e4"]}. Both TypeScript and Python convert it to and from native objects.
A10: Concept 5 | B10: HTTPS = HTTP inside an encrypted TLS tunnel. Tokens and passwords must only ever travel over HTTPS. Vercel and Render give you HTTPS automatically.
A11: Concept 6 | B11: Statelessness: each HTTP request stands alone. The server remembers who you are only because the browser sends a token with every request; durable memory lives in the database, never in a Python variable.
A12: Concept 7 | B12: Origins: an origin is scheme + host + port (https://chesslab.vercel.app and https://chesslab-api.onrender.com are DIFFERENT origins). Browsers restrict JavaScript talking across origins; that is why CORS (lesson L21) exists.
A13: In ChessLab | B13: The React app calls fetch('https://<api>/v1/games', {method: 'POST', headers: {Authorization: 'Bearer ...'}, body: JSON.stringify({...})}). FastAPI receives it, validates the JSON, writes rows to Postgres, and returns 201 with JSON. You can watch every such request in the browser's DevTools > Network tab: make that a habit.
A14: Common mistake | B14: Thinking the frontend and backend are 'one program'. They are separate programs, deployed separately, talking over the network.
A15: Common mistake | B15: Putting secrets in frontend code. Anything shipped to the browser is public.
A16: Common mistake | B16: Ignoring status codes and only reading the body. The status code tells you what kind of failure happened.
... A25: L02 | B25: The terminal on Windows: Git Bash, paths and environment variables · Beginner · about 45 min · used in P0 and every phase
B26: ↑ back to Lessons index
A27: Why it matters | B27: You will run hundreds of commands, and every one in this manual is written for Git Bash. Most beginner frustration comes from the wrong folder, a stale PATH, or Git Bash's path conversion. This lesson removes all three.
A28: Concept 1 | B28: Git Bash comes with Git for Windows. It gives you a Unix-style shell (bash) on Windows, so the same commands work on Linux servers, in Docker containers and in GitHub Actions. git, npm, uv, docker and gh all run inside it.
A29: Concept 2 | B29: Paths: Git Bash writes drives as /d/my_learning/Chess-AI instead of D:\my_learning\Chess-AI. Your home folder is ~ (C:/Users/<you>). Windows programs called from Git Bash usually accept both styles. Quote paths that contain spaces.
A30: Concept 3 | B30: Working directory: commands run relative to your current folder. cd moves, pwd shows where you are, ls -la lists files. Most 'file not found' errors mean you are in the wrong folder.
A31: Concept 4 | B31: Environment variables: export NAME=value sets one for this session; echo $NAME prints it. A program only sees variables set BEFORE it started, so restart it after a change. Lines in ~/.bashrc run in every new Git Bash window and affect every project, so keep project settings out of it.
A32: Concept 5 | B32: PATH lists folders where the shell looks for programs. 'command not found' straight after installing something usually means: close and reopen Git Bash.
A33: Concept 6 | B33: Chaining: a && b runs b only if a succeeded; a || b runs b only if a failed; a | b sends a's output into b (grep, head, tail filter output). These replace PowerShell's ';', Select-String and Select-Object.
A34: Concept 7 | B34: Path conversion: when Git Bash calls a Windows program it rewrites arguments that look like Unix paths, so /usr/games/stockfish becomes C:/Program Files/Git/usr/games/stockfish. Paths INSIDE a Docker container must not be rewritten: prefix such docker commands with MSYS_NO_PATHCONV=1 (the manual does this for you). For volume mounts use "$(pwd -W)", which prints the Windows form of the current folder.
A35: Concept 8 | B35: Heredocs: cmd <<'EOF' ... EOF feeds several lines into a command or file (P2.07 uses one to send SQL to psql).
A36: Concept 9 | B36: Ports: a server listens on a port. Two programs cannot share one. On Srikanth's laptop 5432, 8000 and 5173 are already used by other projects, so ChessLab uses 5433, 8010 and 5180 on both laptops.
A37: In ChessLab | B37: Every command in this manual is written for Git Bash. Docker commands that contain container paths start with MSYS_NO_PATHCONV=1.
A38: Common mistake | B38: Running a command in the wrong folder (for example npm install in the repo root instead of apps/web).
... A50: L03 | B50: Git and GitHub: commits, branches, pull requests · Beginner · about 75 min · used in P0, P1 and every phase
B51: ↑ back to Lessons index
A52: Why it matters | B52: Git is your undo button, your history, and the way you deploy (Vercel and Render deploy from GitHub). Recruiters also read your commit history.
A53: Concept 1 | B53: A commit is a snapshot of the project with a message explaining WHY something changed. Commit small, coherent steps (one feature or fix each).
A54: Concept 2 | B54: The staging area: 'git add <file>' chooses what goes into the next commit; 'git commit -m "..."' records it. 'git status' and 'git diff' show what changed. Run them constantly.
A55: Concept 3 | B55: Branches let you try something risky without touching main (git switch -c experiment). In this project the two of you mostly work directly on main and push small commits.
A56: Concept 4 | B56: Remote: GitHub holds a copy (origin). 'git push' uploads commits; 'git pull' downloads. Vercel/Render watch a branch and redeploy on every push.
A57: Concept 5 | B57: Never commit secrets (.env), build output (dist/, node_modules/) or huge data files. .gitignore lists what Git should ignore. If you commit a secret, rotating (changing) the secret is mandatory; deleting the file is not enough because history keeps it.
A58: Concept 6 | B58: Tags mark releases (git tag v1.0.0) and give you a known-good revision to roll back to.
A59: Concept 7 | B59: Conventional commit messages (feat:, fix:, docs:, test:, chore:) make history readable.
A60: In ChessLab | B60: G0 connected this folder to GitHub and tagged the original app (original-app). Every step that changes files ends with pull, commit, push to main. Render and Vercel deploy main, so keep it working.
...

Sheet Code Index
A1: ID | B1: File path (relative to repo root) | C1: Phase | D1: What it is for | E1: Lines | F1: Open
A2: C01 | B2: .gitignore | C2: G0 | D2: Keeps Office lock files, dependencies, caches, secrets and large data out of Git. | E2: 21 | F2: View →
A3: C02 | B3: compose.yaml | C3: P2 | D3: Local stack: Postgres (5433), API (8010, runs migrations first), worker. | E3: 49 | F3: View →
A4: C03 | B4: services/backend/pyproject.toml | C4: P2 | D4: Backend dependencies (reference) and pytest/ruff settings. | E4: 30 | F4: View →
A5: C04 | B5: services/backend/.env.example | C5: P3 | D5: Every backend setting with safe local defaults. Copy to .env. | E5: 19 | F5: View →
A6: C05 | B6: services/backend/app/config.py | C6: P3 | D6: Typed settings from environment variables; fixes Render's postgres:// URL. | E6: 59 | F6: View →
A7: C06 | B7: services/backend/app/db.py | C7: P3 | D7: SQLAlchemy engine (bounded pool) and one session per request. | E7: 27 | F7: View →
A8: C07 | B8: services/backend/app/models.py | C8: P3 | D8: All 10 tables with database-level constraints. | E8: 220 | F8: View →
A9: C08 | B9: services/backend/migrations/env.py.additions | C9: P3 | D9: The 3 edits to Alembic's generated env.py. | E9: 13 | F9: View →
A10: C09 | B10: services/backend/app/errors.py | C10: P3 | D10: Uniform error JSON; tracebacks only in logs. | E10: 39 | F10: View →
A11: C10 | B11: services/backend/app/security.py | C11: P3 | D11: Guest tokens: generate, hash, authenticate, sliding expiry. | E11: 47 | F11: View →
A12: C11 | B12: services/backend/app/ratelimit.py | C12: P3 | D12: Small per-IP sliding-window rate limiter dependency. | E12: 37 | F12: View →
A13: C12 | B13: services/backend/app/api/sessions.py | C13: P3 | D13: POST /v1/sessions and GET /v1/me. | E13: 40 | F13: View →
... A94: C93 | B94: evaluation/compare_models.py | C94: S6 | D94: Constant vs Elo vs logistic regression on held-out attempts. | E94: 61 | F94: View →

Sheet Code
A1: Code library: every file below was written for this plan and (except deployment-only files) run and tested. Copy each file to the path shown in its header. Line numbers are for reference only; do not copy them.
A3: C01 | B3: .gitignore · Phase G0 · Keeps Office lock files, dependencies, caches, secrets and large data out of Git.
B4: ↑ back to Code Index
A5: 1 | B5: # Python
A6: 2 | B6: __pycache__/
A7: 3 | B7: *.pyc
A8: 4 | B8: .venv/
A9: 5 | B9: .pytest_cache/
A10: 6 | B10: .ruff_cache/
A11: 7 | B11: # Node
A12: 8 | B12: node_modules/
A13: 9 | B13: dist/
A14: 10 | B14: playwright-report/
A15: 11 | B15: test-results/
A16: 12 | B16: # Office lock files (Excel creates ~$name.xlsx while a workbook is open)
A17: 13 | B17: ~$*
A18: 14
A19: 15 | B19: # Secrets and local config
A20: 16 | B20: .env
A21: 17 | B21: .env.local
A22: 18 | B22: *.local
A23: 19 | B23: # Data: commit manifests and the small subset, never the full Lichess dump
A24: 20 | B24: *.csv.zst
A25: 21 | B25: data/raw/
A28: C02 | B28: compose.yaml · Phase P2 · Local stack: Postgres (5433), API (8010, runs migrations first), worker.
B29: ↑ back to Code Index
A30: 1 | B30: # Local stack: docker compose up --build
A31: 2 | B31: # db = Postgres, api = FastAPI on :8000, worker = job runner with Stockfish. The frontend runs with `npm run dev`.
A32: 3 | B32: services:
A33: 4 | B33: db:
A34: 5 | B34: image: postgres:16
A35: 6 | B35: environment:
A36: 7 | B36: POSTGRES_USER: chesslab
A37: 8 | B37: POSTGRES_PASSWORD: chesslab
A38: 9 | B38: POSTGRES_DB: chesslab
A39: 10 | B39: ports:
A40: 11 | B40: - "5433:5432" # host port 5433, because 5432 is often taken by another Postgres
A41: 12 | B41: volumes:
... A47: 18 | B47: retries: 20
A48: 19
...

Sheet API Reference
A1: Method | B1: Path | C1: Auth | D1: Request body | E1: Response | F1: Success | G1: Error codes
A2: POST | B2: /v1/sessions | C2: No (rate-limited) | D2: — | E2: {token, visitor_id, expires_at} | F2: 201 | G2: RATE_LIMITED
A3: GET | B3: /v1/me | C3: Bearer | D3: — | E3: {visitor_id, expires_at} | F3: 200 | G3: AUTH_REQUIRED, AUTH_INVALID
A4: POST | B4: /v1/games | C4: Bearer | D4: {pgn, player_color, engine_label} | E4: {game_id, analysis_job_id} | F4: 201 | G4: INVALID_PGN, VALIDATION_FAILED
A5: GET | B5: /v1/games | C5: Bearer | D5: — | E5: [GameSummary] | F5: 200
A6: GET | B6: /v1/games/{id} | C6: Bearer (owner) | D6: — | E6: GameDetail (pgn, initial_fen ...) | F6: 200 | G6: GAME_NOT_FOUND
A7: POST | B7: /v1/games/{id}/analysis | C7: Bearer (owner) | D7: — | E7: {game_id, analysis_job_id} | F7: 202 | G7: GAME_NOT_FOUND
A8: GET | B8: /v1/games/{id}/review | C8: Bearer (owner) | D8: — | E8: Review (state, coverage, findings[]) | F8: 200 | G8: GAME_NOT_FOUND
A9: GET | B9: /v1/demo/review | C9: No | D9: — | E9: Review (is_demo = true) | F9: 200 | G9: DEMO_MISSING
A10: POST | B10: /v1/imports | C10: Bearer | D10: {provider, username, max_games<=200} | E10: ImportRun | F10: 202 | G10: IMPORT_RATE_LIMITED, VALIDATION_FAILED
A11: POST | B11: /v1/imports/pgn | C11: Bearer | D11: multipart: file, player_name?, player_color | E11: {import_id, accepted, duplicates, errors[]} | F11: 202 | G11: UPLOAD_TOO_LARGE
A12: GET | B12: /v1/imports/{id} | C12: Bearer (owner) | D12: — | E12: ImportRun (fetched, eligible, excluded, analyzed) | F12: 200 | G12: IMPORT_NOT_FOUND
A13: GET | B13: /v1/jobs/{id} | C13: Bearer (owner) | D13: — | E13: {status, attempts, progress, error_code} | F13: 200 | G13: JOB_NOT_FOUND
A14: POST | B14: /v1/jobs/{id}/cancel | C14: Bearer (owner) | D14: — | E14: {status} | F14: 200 | G14: JOB_NOT_FOUND
A15: POST | B15: /v1/practice/sessions | C15: Bearer | D15: {concept?, evidence_id?, mode} | E15: PracticeSession (no solution!) | F15: 201 | G15: NO_PUZZLE_AVAILABLE, EVIDENCE_NOT_FOUND
A16: GET | B16: /v1/practice/sessions/{id} | C16: Bearer (owner) | D16: — | E16: PracticeSession | F16: 200 | G16: SESSION_NOT_FOUND
A17: POST | B17: /v1/practice/sessions/{id}/moves | C17: Bearer (owner) | D17: {uci} | E17: {outcome, fen, opponent_reply_uci, state, first_try_success, rating_after} | F17: 200 | G17: ILLEGAL_MOVE, SESSION_FINISHED
... A19: POST | B19: /v1/practice/sessions/{id}/give-up | C19: Bearer (owner) | D19: — | E19: MoveResult (final position) | F19: 200 | G19: SESSION_FINISHED
A20: GET | B20: /v1/progress | C20: Bearer | D20: — | E20: {concepts[], note} | F20: 200
A21: DELETE | B21: /v1/me/data | C21: Bearer | D21: — | E21: (empty) | F21: 204
A22: GET | B22: /health/live | C22: No | D22: — | E22: {status: ok} | F22: 200
A23: GET | B23: /health/ready | C23: No | D23: — | E23: {status: ready, environment} | F23: 200 | G23: 500 if DB unreachable
A25: Error shape for every failure: {"error": {"code": "STABLE_CODE", "message": "Human text"}}. Interactive docs: http://localhost:8010/docs (and /docs on your Render URL).

Sheet Config & Env
